Traceback (most recent call last):
  File "/home/paul/Downloads/prod/location_app/main.py", line 147, in <module>
    main()
  File "/home/paul/Downloads/prod/location_app/main.py", line 135, in main
    scraper(
  File "/home/paul/Downloads/prod/location_app/main.py", line 100, in scraper
    login(driver, url, email, password)
  File "/home/paul/Downloads/prod/location_app/main.py", line 33, in login
    driver.get(f"{scheme}://{email}:{password}@{domain}{path}")
  File "/home/paul/miniconda3/envs/tfs/lib/python3.11/site-packages/selenium/webdriver/remote/webdriver.py", line 449, in get
    self.execute(Command.GET, {"url": url})
  File "/home/paul/miniconda3/envs/tfs/lib/python3.11/site-packages/selenium/webdriver/remote/webdriver.py", line 440, in execute
    self.error_handler.check_response(response)
  File "/home/paul/miniconda3/envs/tfs/lib/python3.11/site-packages/selenium/webdriver/remote/errorhandler.py", line 245, in check_response
    raise exception_class(message, screen, stacktrace)
selenium.common.exceptions.InvalidArgumentException: Message: invalid argument
  (Session info: chrome=112.0.5615.165)
Stacktrace:

